<robot name="unnamed" version="1.0">
  <joint name="joint1" type="revolute">
    <limit lower="-3.14159" upper="3.14159" effort="0.00000" velocity="0.00000"/>
    <origin rpy="-0.00000 -0.00000 0.00000" xyz="16.256 -0.00000 20.102"/>
    <parent link="base_link"/>
    <child link="Cylinder.011_link"/>
    <axis xyz="0.00000 0.00000 1.00000"/>
  </joint>
  <joint name="joint2" type="revolute">
    <limit lower="-1.04720" upper="1.57080" effort="0.00000" velocity="0.00000"/>
    <origin rpy="1.57080 0.00000 0.00000" xyz="1.144 -0.00000 31.668"/>
    <parent link="Cylinder.011_link"/>
    <child link="Cylinder.003_link"/>
    <axis xyz="0.00000 0.00000 1.00000"/>
  </joint>
  <joint name="joint3" type="revolute">
    <limit lower="-1.57080" upper="1.04720" effort="0.00000" velocity="0.00000"/>
    <origin rpy="0.00000 0.00000 0.00000" xyz="-14.992 23.956 -0.008"/>
    <parent link="Cylinder.003_link"/>
    <child link="Cylinder.004_link"/>
    <axis xyz="0.00000 0.00000 1.00000"/>
  </joint>
  <joint name="joint4" type="revolute">
    <limit lower="-1.57080" upper="0.87266" effort="0.00000" velocity="0.00000"/>
    <origin rpy="0.00000 0.00000 0.00000" xyz="9.792 20.674 0.008"/>
    <parent link="Cylinder.004_link"/>
    <child link="Cylinder.005_link"/>
    <axis xyz="0.00000 0.00000 1.00000"/>
  </joint>
  <joint name="joint5" type="revolute">
    <limit lower="-1.57080" upper="1.57080" effort="0.00000" velocity="0.00000"/>
    <origin rpy="-1.57080 0.00000 -1.57080" xyz="21.772 1.444 -0.008"/>
    <parent link="Cylinder.005_link"/>
    <child link="Cylinder.002_link"/>
    <axis xyz="0.00000 0.00000 1.00000"/>
  </joint>
  <joint name="joint6" type="revolute">
    <limit lower="-1.57080" upper="0.52360" effort="0.00000" velocity="0.00000"/>
    <origin rpy="1.57080 -1.57080 0.00000" xyz="0.258 -0.008 23.624"/>
    <parent link="Cylinder.002_link"/>
    <child link="Cylinder.009_link"/>
    <axis xyz="0.00000 0.00000 1.00000"/>
  </joint>
  <joint name="joint7" type="prismatic">
    <limit lower="0.00000" upper="20.00000" effort="0.00000" velocity="0.00000"/>
    <origin rpy="-1.57080 0.00000 3.14159" xyz="20.638 -58.184 0.00000"/>
    <parent link="Cylinder.009_link"/>
    <child link="Cylinder.001_link"/>
    <axis xyz="0.00000 0.00000 1.00000"/>
  </joint>
  <link name="Cylinder.001_link"/>
  <link name="Cylinder.002_link"/>
  <link name="Cylinder.003_link"/>
  <link name="Cylinder.004_link"/>
  <link name="Cylinder.005_link"/>
  <link name="Cylinder.009_link"/>
  <link name="Cylinder.011_link"/>
  <link name="base_link"/>
  <link name="vertical_tool"/>
  <joint name="tool_attachment_joint" type="fixed">
    <parent link="Cylinder.001_link"/>
    <child link="vertical_tool"/>
    <origin xyz="0 0 0" rpy="0 0 0"/>
  </joint>
</robot>